Workbook

Sheet Summary
A1: RAG Evaluation - Evaluation notebook
A3: Run date | B3: 2026-10-14 19:53
A4: Notebook | B4: Evaluation (d42b50e62aa64466bef9f3e6133675c9)
A5: Sources | B5: Business analytics - Wikipedia (URL); Business Analytics Overview.pptx; Business_Analytics_Textbook_Cengage_pg_1_300.pdf; Business_Analytics_Study_Guide_UNCC.pdf
A6: Methods compared | B6: keyword, vector, hybrid, hybrid_semantic
A7: Top-k | B7: 5
A8: Chunking | B8: Recursive character, size 1200, overlap 200
A9: Embedding model | B9: qwen3-embedding (2560 dims)
A10: LLM | B10: qwen3.8-27b
A11: Data source | B11: eval/results/eval-20261014-195319.json (generated by eval/run_eval.py)
A13: How to use this workbook
A14: Yellow cells are yours to fill in: 'Answer quality', 'Citations correct?' and 'Notes' on the Per Question sheet, and Conclusions below.
A15: Answer quality: Good = correct, complete, right citations · Partial = mostly right or some citation problems · Poor = wrong, invented, or wrongly says the sources don't cover it.
A16: Read each answer on the Answers sheet (its grade column mirrors what you enter on Per Question). Retrieved chunks are on the Retrieved Chunks sheet.
A17: Example of a filled-in row: Answer quality = Good | Citations correct? = Yes | Notes = "Lists all four Vs, cites textbook p.32".
A18: All numbers in the tables below are formulas over the Per Question sheet and update as you grade.
A20: Retrieval comparison | C20: Hit rate = share of scored questions with at least one relevant chunk in the top-k. MRR = mean reciprocal rank of the first relevant chunk (1.0 = always first).
A21: Method | B21: Hit rate | C21: MRR | D21: Avg relevant chunks | E21: Avg retrieval time (s) | F21: Avg generation time (s) | G21: Avg total response time (s)
A22: keyword | B22: =AVERAGEIFS('Per Question'!$I$2:$I$33,'Per Question'!$D$2:$D$33,$A22,'Per Question'!$F$2:$F$33,"Yes") | C22: =AVERAGEIFS('Per Question'!$J$2:$J$33,'Per Question'!$D$2:$D$33,$A22,'Per Question'!$F$2:$F$33,"Yes") | D22: =AVERAGEIFS('Per Question'!$G$2:$G$33,'Per Question'!$D$2:$D$33,$A22,'Per Question'!$F$2:$F$33,"Yes") | E22: =AVERAGEIF('Per Question'!$D$2:$D$33,$A22,'Per Question'!$K$2:$K$33) | F22: =AVERAGEIF('Per Question'!$D$2:$D$33,$A22,'Per Question'!$L$2:$L$33) | G22: =AVERAGEIF('Per Question'!$D$2:$D$33,$A22,'Per Question'!$M$2:$M$33)
A23: vector | B23: =AVERAGEIFS('Per Question'!$I$2:$I$33,'Per Question'!$D$2:$D$33,$A23,'Per Question'!$F$2:$F$33,"Yes") | C23: =AVERAGEIFS('Per Question'!$J$2:$J$33,'Per Question'!$D$2:$D$33,$A23,'Per Question'!$F$2:$F$33,"Yes") | D23: =AVERAGEIFS('Per Question'!$G$2:$G$33,'Per Question'!$D$2:$D$33,$A23,'Per Question'!$F$2:$F$33,"Yes") | E23: =AVERAGEIF('Per Question'!$D$2:$D$33,$A23,'Per Question'!$K$2:$K$33) | F23: =AVERAGEIF('Per Question'!$D$2:$D$33,$A23,'Per Question'!$L$2:$L$33) | G23: =AVERAGEIF('Per Question'!$D$2:$D$33,$A23,'Per Question'!$M$2:$M$33)
A24: hybrid | B24: =AVERAGEIFS('Per Question'!$I$2:$I$33,'Per Question'!$D$2:$D$33,$A24,'Per Question'!$F$2:$F$33,"Yes") | C24: =AVERAGEIFS('Per Question'!$J$2:$J$33,'Per Question'!$D$2:$D$33,$A24,'Per Question'!$F$2:$F$33,"Yes") | D24: =AVERAGEIFS('Per Question'!$G$2:$G$33,'Per Question'!$D$2:$D$33,$A24,'Per Question'!$F$2:$F$33,"Yes") | E24: =AVERAGEIF('Per Question'!$D$2:$D$33,$A24,'Per Question'!$K$2:$K$33) | F24: =AVERAGEIF('Per Question'!$D$2:$D$33,$A24,'Per Question'!$L$2:$L$33) | G24: =AVERAGEIF('Per Question'!$D$2:$D$33,$A24,'Per Question'!$M$2:$M$33)
A25: hybrid_semantic | B25: =AVERAGEIFS('Per Question'!$I$2:$I$33,'Per Question'!$D$2:$D$33,$A25,'Per Question'!$F$2:$F$33,"Yes") | C25: =AVERAGEIFS('Per Question'!$J$2:$J$33,'Per Question'!$D$2:$D$33,$A25,'Per Question'!$F$2:$F$33,"Yes") | D25: =AVERAGEIFS('Per Question'!$G$2:$G$33,'Per Question'!$D$2:$D$33,$A25,'Per Question'!$F$2:$F$33,"Yes") | E25: =AVERAGEIF('Per Question'!$D$2:$D$33,$A25,'Per Question'!$K$2:$K$33) | F25: =AVERAGEIF('Per Question'!$D$2:$D$33,$A25,'Per Question'!$L$2:$L$33) | G25: =AVERAGEIF('Per Question'!$D$2:$D$33,$A25,'Per Question'!$M$2:$M$33)
A28: Answer quality (from your grades) | C28: Quality score = (2 x Good + 1 x Partial) / (2 x graded). Blank until you grade.
A29: Method | B29: Graded | C29: Good | D29: Partial | E29: Poor | F29: Quality score | G29: Citations correct (Yes)
A30: keyword | B30: =COUNTIFS('Per Question'!$D$2:$D$33,$A30,'Per Question'!$N$2:$N$33,"Good")+COUNTIFS('Per Question'!$D$2:$D$33,$A30,'Per Question'!$N$2:$N$33,"Partial")+COUNTIFS('Per Question'!$D$2:$D$33,$A30,'Per Question'!$N$2:$N$33,"Poor") | C30: =COUNTIFS('Per Question'!$D$2:$D$33,$A30,'Per Question'!$N$2:$N$33,"Good") | D30: =COUNTIFS('Per Question'!$D$2:$D$33,$A30,'Per Question'!$N$2:$N$33,"Partial") | E30: =COUNTIFS('Per Question'!$D$2:$D$33,$A30,'Per Question'!$N$2:$N$33,"Poor") | F30: =IF(B30=0,"",(2*C30+D30)/(2*B30)) | G30: =COUNTIFS('Per Question'!$D$2:$D$33,$A30,'Per Question'!$O$2:$O$33,"Yes")
A31: vector | B31: =COUNTIFS('Per Question'!$D$2:$D$33,$A31,'Per Question'!$N$2:$N$33,"Good")+COUNTIFS('Per Question'!$D$2:$D$33,$A31,'Per Question'!$N$2:$N$33,"Partial")+COUNTIFS('Per Question'!$D$2:$D$33,$A31,'Per Question'!$N$2:$N$33,"Poor") | C31: =COUNTIFS('Per Question'!$D$2:$D$33,$A31,'Per Question'!$N$2:$N$33,"Good") | D31: =COUNTIFS('Per Question'!$D$2:$D$33,$A31,'Per Question'!$N$2:$N$33,"Partial") | E31: =COUNTIFS('Per Question'!$D$2:$D$33,$A31,'Per Question'!$N$2:$N$33,"Poor") | F31: =IF(B31=0,"",(2*C31+D31)/(2*B31)) | G31: =COUNTIFS('Per Question'!$D$2:$D$33,$A31,'Per Question'!$O$2:$O$33,"Yes")
A32: hybrid | B32: =COUNTIFS('Per Question'!$D$2:$D$33,$A32,'Per Question'!$N$2:$N$33,"Good")+COUNTIFS('Per Question'!$D$2:$D$33,$A32,'Per Question'!$N$2:$N$33,"Partial")+COUNTIFS('Per Question'!$D$2:$D$33,$A32,'Per Question'!$N$2:$N$33,"Poor") | C32: =COUNTIFS('Per Question'!$D$2:$D$33,$A32,'Per Question'!$N$2:$N$33,"Good") | D32: =COUNTIFS('Per Question'!$D$2:$D$33,$A32,'Per Question'!$N$2:$N$33,"Partial") | E32: =COUNTIFS('Per Question'!$D$2:$D$33,$A32,'Per Question'!$N$2:$N$33,"Poor") | F32: =IF(B32=0,"",(2*C32+D32)/(2*B32)) | G32: =COUNTIFS('Per Question'!$D$2:$D$33,$A32,'Per Question'!$O$2:$O$33,"Yes")
A33: hybrid_semantic | B33: =COUNTIFS('Per Question'!$D$2:$D$33,$A33,'Per Question'!$N$2:$N$33,"Good")+COUNTIFS('Per Question'!$D$2:$D$33,$A33,'Per Question'!$N$2:$N$33,"Partial")+COUNTIFS('Per Question'!$D$2:$D$33,$A33,'Per Question'!$N$2:$N$33,"Poor") | C33: =COUNTIFS('Per Question'!$D$2:$D$33,$A33,'Per Question'!$N$2:$N$33,"Good") | D33: =COUNTIFS('Per Question'!$D$2:$D$33,$A33,'Per Question'!$N$2:$N$33,"Partial") | E33: =COUNTIFS('Per Question'!$D$2:$D$33,$A33,'Per Question'!$N$2:$N$33,"Poor") | F33: =IF(B33=0,"",(2*C33+D33)/(2*B33)) | G33: =COUNTIFS('Per Question'!$D$2:$D$33,$A33,'Per Question'!$O$2:$O$33,"Yes")
A36: Conclusions
A37: Which method retrieved the most relevant chunks? | B37: Vector search found a relevant chunk for every scored question (hit rate 100%, MRR 0.86). Hybrid + semantic re-ranking retrieved the most relevant chunks per question (2.1 of 5) and was the only method that pulled both the textbook and the Wikipedia page to the top for the multi-source question (Q5: 4 of 5 relevant, first at rank 1). Keyword search missed both paraphrased questions (Q3, Q7), giving the lowest hit rate (71%) and MRR (0.57).
A38: How did answer quality differ between methods? | B38: Hybrid + semantic answered all 8 questions well (quality score 100%, citations correct on all 8), followed by hybrid (94%), vector (88%) and keyword (81%). Keyword's weak spot was paraphrase: nothing relevant for Q3 (Poor) and only a partial answer for Q7. All four methods handled the exact term (Q4), the specific number (Q2) and the unanswerable question (Q8) correctly. On Q7 the grades disagree with the automatic score: the hybrid methods used the textbook's data-quality pages instead of the slides and still gave complete answers.
A39: What did each method cost in response time? | B39: Retrieval is a small share of the response: keyword 0.13 s, hybrid + semantic 0.84 s, vector 1.02 s, hybrid 1.24 s (the vector-based methods include embedding the question). Total response time is dominated by LLM generation: hybrid + semantic 9.1 s on average, keyword 9.5 s, vector 9.5 s, hybrid 12.9 s (raised by one 33 s answer on Q7). Better-ranked context tended to produce faster answers (Q5: 16.8 s with semantic re-ranking vs. 23-29 s for the other methods).
A40: Which method did you select as the default, and why? | B40: Hybrid + semantic re-ranking. It gave the best answer quality and citation accuracy, retrieved the most relevant chunks per question, handled multi-source and paraphrased questions best, and had the lowest average total response time; its ~0.7 s retrieval overhead over keyword search is negligible next to generation time. Vector search alone had a slightly higher hit rate and MRR on this small set, but re-ranking produced better final answers. Caveat: 8 questions and one run each, so time differences under ~2 s are within run-to-run noise.
A42: Observations to consider
A43: Q7 is scored against the slides only, but the hybrid methods retrieved the textbook's own data-quality pages (p. 30, 34, 49); judge Q7 from the answers, not the hit/miss marks.
A44: Q1's terms also appear in the textbook's table of contents; only chunks that explain the four Vs count as relevant.
A45: 136 of the textbook's 921 chunks (15%) are repeated Cengage copyright notices, and the Wikipedia page's scraped text is fragmented into short lines; both add noise to retrieval.
A46: Retrieval is a small part of total response time; most of it is the LLM generating the answer.

Sheet Per Question
A1: Q# | B1: Question | C1: Type | D1: Method | E1: Retrieved chunks | F1: Scored? | G1: Relevant chunks | H1: First relevant rank | I1: Hit (1/0) | J1: Reciprocal rank | K1: Retrieval time (s) | L1: Generation time (s) | M1: Total response time (s) | N1: Answer quality | O1: Citations correct? | P1: Notes
A2: 1 | B2: According to the textbook, what are the four Vs that IBM uses to describe big data? | C2: Factual | D2: keyword | E2: 5 | F2: Yes | G2: 3 | H2: 2 | I2: =IF(F2="No","",IF(ISNUMBER(H2),1,0)) | J2: =IF(F2="No","",IF(ISNUMBER(H2),1/H2,0)) | K2: 0.391 | L2: 5.23 | M2: 5.622 | N2: Good | O2: Yes
A3: 1 | B3: According to the textbook, what are the four Vs that IBM uses to describe big data? | C3: Factual | D3: vector | E3: 5 | F3: Yes | G3: 3 | H3: 1 | I3: =IF(F3="No","",IF(ISNUMBER(H3),1,0)) | J3: =IF(F3="No","",IF(ISNUMBER(H3),1/H3,0)) | K3: 0.974 | L3: 3.409 | M3: 4.383 | N3: Good | O3: Yes
A4: 1 | B4: According to the textbook, what are the four Vs that IBM uses to describe big data? | C4: Factual | D4: hybrid | E4: 5 | F4: Yes | G4: 3 | H4: 1 | I4: =IF(F4="No","",IF(ISNUMBER(H4),1,0)) | J4: =IF(F4="No","",IF(ISNUMBER(H4),1/H4,0)) | K4: 0.979 | L4: 3.334 | M4: 4.314 | N4: Good | O4: Yes
A5: 1 | B5: According to the textbook, what are the four Vs that IBM uses to describe big data? | C5: Factual | D5: hybrid_semantic | E5: 5 | F5: Yes | G5: 3 | H5: 1 | I5: =IF(F5="No","",IF(ISNUMBER(H5),1,0)) | J5: =IF(F5="No","",IF(ISNUMBER(H5),1/H5,0)) | K5: 0.87 | L5: 3.098 | M5: 3.968 | N5: Good | O5: Yes
A6: 2 | B6: How many pieces of direct mail does Kroger send to its customers each quarter, and how are the coupons chosen? | C6: Factual (number) | D6: keyword | E6: 5 | F6: Yes | G6: 1 | H6: 1 | I6: =IF(F6="No","",IF(ISNUMBER(H6),1,0)) | J6: =IF(F6="No","",IF(ISNUMBER(H6),1/H6,0)) | K6: 0.099 | L6: 6.117 | M6: 6.216 | N6: Good | O6: Yes
A7: 2 | B7: How many pieces of direct mail does Kroger send to its customers each quarter, and how are the coupons chosen? | C7: Factual (number) | D7: vector | E7: 5 | F7: Yes | G7: 1 | H7: 2 | I7: =IF(F7="No","",IF(ISNUMBER(H7),1,0)) | J7: =IF(F7="No","",IF(ISNUMBER(H7),1/H7,0)) | K7: 0.981 | L7: 4.403 | M7: 5.384 | N7: Good | O7: Yes
A8: 2 | B8: How many pieces of direct mail does Kroger send to its customers each quarter, and how are the coupons chosen? | C8: Factual (number) | D8: hybrid | E8: 5 | F8: Yes | G8: 1 | H8: 1 | I8: =IF(F8="No","",IF(ISNUMBER(H8),1,0)) | J8: =IF(F8="No","",IF(ISNUMBER(H8),1/H8,0)) | K8: 1.189 | L8: 4.644 | M8: 5.833 | N8: Good | O8: Yes
A9: 2 | B9: How many pieces of direct mail does Kroger send to its customers each quarter, and how are the coupons chosen? | C9: Factual (number) | D9: hybrid_semantic | E9: 5 | F9: Yes | G9: 1 | H9: 1 | I9: =IF(F9="No","",IF(ISNUMBER(H9),1,0)) | J9: =IF(F9="No","",IF(ISNUMBER(H9),1/H9,0)) | K9: 0.698 | L9: 4.336 | M9: 5.034 | N9: Good | O9: Yes
A10: 3 | B10: What share of data science initiatives end up not succeeding, and what typically goes wrong? | C10: Paraphrase | D10: keyword | E10: 5 | F10: Yes | G10: 0 | H10: none | I10: =IF(F10="No","",IF(ISNUMBER(H10),1,0)) | J10: =IF(F10="No","",IF(ISNUMBER(H10),1/H10,0)) | K10: 0.098 | L10: 10.345 | M10: 10.443 | N10: Poor | O10: Partly
A11: 3 | B11: What share of data science initiatives end up not succeeding, and what typically goes wrong? | C11: Paraphrase | D11: vector | E11: 5 | F11: Yes | G11: 1 | H11: 1 | I11: =IF(F11="No","",IF(ISNUMBER(H11),1,0)) | J11: =IF(F11="No","",IF(ISNUMBER(H11),1/H11,0)) | K11: 1.501 | L11: 5.767 | M11: 7.268 | N11: Partial | O11: Partly
A12: 3 | B12: What share of data science initiatives end up not succeeding, and what typically goes wrong? | C12: Paraphrase | D12: hybrid | E12: 5 | F12: Yes | G12: 1 | H12: 4 | I12: =IF(F12="No","",IF(ISNUMBER(H12),1,0)) | J12: =IF(F12="No","",IF(ISNUMBER(H12),1/H12,0)) | K12: 0.785 | L12: 6.746 | M12: 7.53 | N12: Partial | O12: Partly
A13: 3 | B13: What share of data science initiatives end up not succeeding, and what typically goes wrong? | C13: Paraphrase | D13: hybrid_semantic | E13: 5 | F13: Yes | G13: 1 | H13: 3 | I13: =IF(F13="No","",IF(ISNUMBER(H13),1,0)) | J13: =IF(F13="No","",IF(ISNUMBER(H13),1/H13,0)) | K13: 0.851 | L13: 5.181 | M13: 6.031 | N13: Good | O13: Yes
A14: 4 | B14: What is the data-ink ratio? | C14: Exact term | D14: keyword | E14: 5 | F14: Yes | G14: 5 | H14: 1 | I14: =IF(F14="No","",IF(ISNUMBER(H14),1,0)) | J14: =IF(F14="No","",IF(ISNUMBER(H14),1/H14,0)) | K14: 0.09 | L14: 5.994 | M14: 6.084 | N14: Good | O14: Yes
A15: 4 | B15: What is the data-ink ratio? | C15: Exact term | D15: vector | E15: 5 | F15: Yes | G15: 5 | H15: 1 | I15: =IF(F15="No","",IF(ISNUMBER(H15),1,0)) | J15: =IF(F15="No","",IF(ISNUMBER(H15),1/H15,0)) | K15: 0.948 | L15: 8.943 | M15: 9.892 | N15: Good | O15: Yes
A16: 4 | B16: What is the data-ink ratio? | C16: Exact term | D16: hybrid | E16: 5 | F16: Yes | G16: 5 | H16: 1 | I16: =IF(F16="No","",IF(ISNUMBER(H16),1,0)) | J16: =IF(F16="No","",IF(ISNUMBER(H16),1/H16,0)) | K16: 1.784 | L16: 9.239 | M16: 11.023 | N16: Good | O16: Yes
A17: 4 | B17: What is the data-ink ratio? | C17: Exact term | D17: hybrid_semantic | E17: 5 | F17: Yes | G17: 5 | H17: 1 | I17: =IF(F17="No","",IF(ISNUMBER(H17),1,0)) | J17: =IF(F17="No","",IF(ISNUMBER(H17),1/H17,0)) | K17: 0.64 | L17: 6.898 | M17: 7.538 | N17: Good | O17: Yes
A18: 5 | B18: How is business analytics different from business intelligence, and what do descriptive, predictive, and prescriptive analytics each do? | C18: Multi-source | D18: keyword | E18: 5 | F18: Yes | G18: 1 | H18: 2 | I18: =IF(F18="No","",IF(ISNUMBER(H18),1,0)) | J18: =IF(F18="No","",IF(ISNUMBER(H18),1/H18,0)) | K18: 0.103 | L18: 29.377 | M18: 29.48 | N18: Good | O18: Yes
A19: 5 | B19: How is business analytics different from business intelligence, and what do descriptive, predictive, and prescriptive analytics each do? | C19: Multi-source | D19: vector | E19: 5 | F19: Yes | G19: 2 | H19: 2 | I19: =IF(F19="No","",IF(ISNUMBER(H19),1,0)) | J19: =IF(F19="No","",IF(ISNUMBER(H19),1/H19,0)) | K19: 0.528 | L19: 26.685 | M19: 27.213 | N19: Good | O19: Yes
A20: 5 | B20: How is business analytics different from business intelligence, and what do descriptive, predictive, and prescriptive analytics each do? | C20: Multi-source | D20: hybrid | E20: 5 | F20: Yes | G20: 2 | H20: 4 | I20: =IF(F20="No","",IF(ISNUMBER(H20),1,0)) | J20: =IF(F20="No","",IF(ISNUMBER(H20),1/H20,0)) | K20: 0.718 | L20: 22.634 | M20: 23.352 | N20: Good | O20: Yes
A21: 5 | B21: How is business analytics different from business intelligence, and what do descriptive, predictive, and prescriptive analytics each do? | C21: Multi-source | D21: hybrid_semantic | E21: 5 | F21: Yes | G21: 4 | H21: 1 | I21: =IF(F21="No","",IF(ISNUMBER(H21),1,0)) | J21: =IF(F21="No","",IF(ISNUMBER(H21),1/H21,0)) | K21: 0.732 | L21: 16.072 | M21: 16.803 | N21: Good | O21: Yes
A22: 6 | B22: Who were early pioneers of using analytics in business, long before computers? | C22: Paraphrase (web page) | D22: keyword | E22: 5 | F22: Yes | G22: 1 | H22: 1 | I22: =IF(F22="No","",IF(ISNUMBER(H22),1,0)) | J22: =IF(F22="No","",IF(ISNUMBER(H22),1/H22,0)) | K22: 0.114 | L22: 3.808 | M22: 3.922 | N22: Good | O22: Yes
... A25: 6 | B25: Who were early pioneers of using analytics in business, long before computers? | C25: Paraphrase (web page) | D25: hybrid_semantic | E25: 5 | F25: Yes | G25: 1 | H25: 1 | I25: =IF(F25="No","",IF(ISNUMBER(H25),1,0)) | J25: =IF(F25="No","",IF(ISNUMBER(H25),1/H25,0)) | K25: 0.619 | L25: 6.79 | M25: 7.41 | N25: Good | O25: Yes
A26: 7 | B26: What qualities should data have before you trust it for decision making? | C26: Paraphrase | D26: keyword | E26: 5 | F26: Yes | G26: 0 | H26: none | I26: =IF(F26="No","",IF(ISNUMBER(H26),1,0)) | J26: =IF(F26="No","",IF(ISNUMBER(H26),1/H26,0)) | K26: 0.077 | L26: 8.001 | M26: 8.077 | N26: Partial | O26: Partly
A27: 7 | B27: What qualities should data have before you trust it for decision making? | C27: Paraphrase | D27: vector | E27: 5 | F27: Yes | G27: 1 | H27: 1 | I27: =IF(F27="No","",IF(ISNUMBER(H27),1,0)) | J27: =IF(F27="No","",IF(ISNUMBER(H27),1/H27,0)) | K27: 0.431 | L27: 5.29 | M27: 5.721 | N27: Partial | O27: Partly
A28: 7 | B28: What qualities should data have before you trust it for decision making? | C28: Paraphrase | D28: hybrid | E28: 5 | F28: Yes | G28: 0 | H28: none | I28: =IF(F28="No","",IF(ISNUMBER(H28),1,0)) | J28: =IF(F28="No","",IF(ISNUMBER(H28),1/H28,0)) | K28: 1.797 | L28: 31.661 | M28: 33.458 | N28: Good | O28: Yes
A29: 7 | B29: What qualities should data have before you trust it for decision making? | C29: Paraphrase | D29: hybrid_semantic | E29: 5 | F29: Yes | G29: 0 | H29: none | I29: =IF(F29="No","",IF(ISNUMBER(H29),1,0)) | J29: =IF(F29="No","",IF(ISNUMBER(H29),1/H29,0)) | K29: 1.71 | L29: 18.006 | M29: 19.715 | N29: Good | O29: Yes
A30: 8 | B30: What was Amazon's total revenue in 2023? | C30: Unanswerable | D30: keyword | E30: 5 | F30: No | G30: n/a | H30: n/a | I30: =IF(F30="No","",IF(ISNUMBER(H30),1,0)) | J30: =IF(F30="No","",IF(ISNUMBER(H30),1/H30,0)) | K30: 0.083 | L30: 5.854 | M30: 5.938 | N30: Good | O30: No | P30: Correctly says the sources don't contain Amazon's 2023 revenue; no invented figure. Regraded from Poor (declining is the right behavior for an unanswerable question).
A31: 8 | B31: What was Amazon's total revenue in 2023? | C31: Unanswerable | D31: vector | E31: 5 | F31: No | G31: n/a | H31: n/a | I31: =IF(F31="No","",IF(ISNUMBER(H31),1,0)) | J31: =IF(F31="No","",IF(ISNUMBER(H31),1/H31,0)) | K31: 0.714 | L31: 7.12 | M31: 7.834 | N31: Good | O31: No | P31: Correctly says the sources don't contain Amazon's 2023 revenue; no invented figure. Regraded from Poor (declining is the right behavior for an unanswerable question).
A32: 8 | B32: What was Amazon's total revenue in 2023? | C32: Unanswerable | D32: hybrid | E32: 5 | F32: No | G32: n/a | H32: n/a | I32: =IF(F32="No","",IF(ISNUMBER(H32),1,0)) | J32: =IF(F32="No","",IF(ISNUMBER(H32),1/H32,0)) | K32: 0.43 | L32: 8.346 | M32: 8.776 | N32: Good | O32: Yes | P32: Correctly says the sources don't contain Amazon's 2023 revenue; no invented figure. Regraded from Poor (declining is the right behavior for an unanswerable question).
A33: 8 | B33: What was Amazon's total revenue in 2023? | C33: Unanswerable | D33: hybrid_semantic | E33: 5 | F33: No | G33: n/a | H33: n/a | I33: =IF(F33="No","",IF(ISNUMBER(H33),1,0)) | J33: =IF(F33="No","",IF(ISNUMBER(H33),1/H33,0)) | K33: 0.592 | L33: 5.378 | M33: 5.971 | N33: Good | O33: Yes | P33: Correctly says the sources don't contain Amazon's 2023 revenue; no invented figure. Regraded from Poor (declining is the right behavior for an unanswerable question).

Sheet Questions
A1: Q# | B1: Question | C1: Type | D1: Expected source contains | E1: Expected text contains | F1: Note
A2: 1 | B2: According to the textbook, what are the four Vs that IBM uses to describe big data? | C2: Factual | D2: Textbook | E2: four Vs | F2: factual lookup; the terms also appear in table-of-contents chunks, which shouldn't count
A3: 2 | B3: How many pieces of direct mail does Kroger send to its customers each quarter, and how are the coupons chosen? | C3: Factual (number) | D3: Textbook | E3: 11 million | F3: factual lookup of a specific number buried in a 921-chunk textbook
A4: 3 | B4: What share of data science initiatives end up not succeeding, and what typically goes wrong? | C4: Paraphrase | D4: Overview | E4: failure rate | F4: paraphrase: the slide says 'failure rate for analytics project', the question uses different words
A5: 4 | B5: What is the data-ink ratio? | C5: Exact term | E5: data-ink ratio | F5: exact term: keyword search should do well
A6: 5 | B6: How is business analytics different from business intelligence, and what do descriptive, predictive, and prescriptive analytics each do? | C6: Multi-source | E6: prescriptive | F6: multi-source: the BI contrast is on the Wikipedia page, the three categories are in the textbook and Wikipedia; check both are cited
A7: 6 | B7: Who were early pioneers of using analytics in business, long before computers? | C7: Paraphrase (web page) | D7: Wikipedia | E7: Henry Ford | F7: paraphrase over the web page, whose scraped text is fragmented across many short lines
A8: 7 | B8: What qualities should data have before you trust it for decision making? | C8: Paraphrase | D8: Overview | E8: consistent | F8: paraphrase: the slide lists data quality as correct, complete, current, consistent, in context, controlled
A9: 8 | B9: What was Amazon's total revenue in 2023? | C9: Unanswerable | F9: unanswerable: the sources predate 2023 and don't cover it; the answer should say so instead of guessing

Sheet Retrieved Chunks
A1: Q# | B1: Method | C1: Rank | D1: Relevant? | E1: Source | F1: Location | G1: Score | H1: Reranker score | I1: Chunk text (first 220 characters)
A2: 1 | B2: keyword | C2: 1 | D2: No | E2: Business_Analytics_Textbook_Cengage_pg_1_300.pdf | F2: page 278 | G2: 20.216307 | I2: 252 chapter 5 Descriptive Data Mining set of customer profiles (clusters). Describe these clusters according to their “average” characteristics. Why might hierarchical clustering not be a good method to use for these sev...
A3: 1 | B3: keyword | C3: 2 | D3: Yes | E3: Business_Analytics_Textbook_Cengage_pg_1_300.pdf | F3: page 32 | G3: 19.292797 | I3: from aircraft to cars to bridges allow us to collect and store vast amounts of data in real time. In the midst of all of this data collection, the term big data has been created. There is no universally accepted definiti...
A4: 1 | B4: keyword | C4: 3 | D4: Yes | E4: Business_Analytics_Textbook_Cengage_pg_1_300.pdf | F4: page 33 | G4: 16.412907 | I4: 1.4 Big Data 7 Chapter Title Descriptive Predictive Prescriptive 1 Introduction ● ● ● 2 Descriptive Statistics ● 3 Data Visualization ● 4 Probability: An Introduction to Modeling Uncertainty ● 5 Descriptive Data Mining ●...
A5: 1 | B5: keyword | C5: 4 | D5: Yes | E5: Business_Analytics_Textbook_Cengage_pg_1_300.pdf | F5: page 34 | G5: 14.855509 | I5: or ser- vices on social media platforms such as Twitter. Audio data are collected from service calls (on a service call, you will often hear “this call may be monitored for quality control”). Video data collected by in-s...
A6: 1 | B6: keyword | C6: 5 | D6: No | E6: Business_Analytics_Textbook_Cengage_pg_1_300.pdf | F6: page 23 | G6: 13.35677 | I6: Preface xxi ● ● New End-of-Chapter Problems. The fourth edition of this textbook includes more than 20 new problems. We have also revised many of the existing problems to update and improve clarity. Each end-of-chapter p...
A7: 1 | B7: vector | C7: 1 | D7: Yes | E7: Business_Analytics_Textbook_Cengage_pg_1_300.pdf | F7: page 32 | G7: 0.7761598 | I7: from aircraft to cars to bridges allow us to collect and store vast amounts of data in real time. In the midst of all of this data collection, the term big data has been created. There is no universally accepted definiti...
A8: 1 | B8: vector | C8: 2 | D8: Yes | E8: Business_Analytics_Textbook_Cengage_pg_1_300.pdf | F8: page 33 | G8: 0.733809 | I8: 1.4 Big Data 7 Chapter Title Descriptive Predictive Prescriptive 1 Introduction ● ● ● 2 Descriptive Statistics ● 3 Data Visualization ● 4 Probability: An Introduction to Modeling Uncertainty ● 5 Descriptive Data Mining ●...
A9: 1 | B9: vector | C9: 3 | D9: No | E9: Business_Analytics_Textbook_Cengage_pg_1_300.pdf | F9: page 27 | G9: 0.6889862 | I9: Chapter Introduction Contents 1.1 DECISION MAKING 1.2 BUSINESS ANALYTICS DEFINED 1.3 A CATEGORIZATION OF ANALYTICAL METHODS AND MODELS Descriptive Analytics Predictive Analytics Prescriptive Analytics 1.4 BIG DATA Volume...
A10: 1 | B10: vector | C10: 4 | D10: Yes | E10: Business_Analytics_Textbook_Cengage_pg_1_300.pdf | F10: page 34 | G10: 0.6748731 | I10: or ser- vices on social media platforms such as Twitter. Audio data are collected from service calls (on a service call, you will often hear “this call may be monitored for quality control”). Video data collected by in-s...
A11: 1 | B11: vector | C11: 5 | D11: No | E11: Business_Analytics_Textbook_Cengage_pg_1_300.pdf | F11: page 7 | G11: 0.6702072 | I11: Contents ABOUT THE AUTHORS xvii PREFACE xix Chapter 1 introduction 1 1.1 Decision Making 3 1.2 Business Analytics Defined 4 1.3 A Categorization of Analytical Methods and Models 5 Descriptive Analytics 5 Predictive Analy...
A12: 1 | B12: hybrid | C12: 1 | D12: Yes | E12: Business_Analytics_Textbook_Cengage_pg_1_300.pdf | F12: page 32 | G12: 0.033060111 | I12: from aircraft to cars to bridges allow us to collect and store vast amounts of data in real time. In the midst of all of this data collection, the term big data has been created. There is no universally accepted definiti...
A13: 1 | B13: hybrid | C13: 2 | D13: Yes | E13: Business_Analytics_Textbook_Cengage_pg_1_300.pdf | F13: page 33 | G13: 0.032522473 | I13: 1.4 Big Data 7 Chapter Title Descriptive Predictive Prescriptive 1 Introduction ● ● ● 2 Descriptive Statistics ● 3 Data Visualization ● 4 Probability: An Introduction to Modeling Uncertainty ● 5 Descriptive Data Mining ●...
... A16: 1 | B16: hybrid | C16: 5 | D16: No | E16: Business_Analytics_Textbook_Cengage_pg_1_300.pdf | F16: page 35 | G16: 0.028438887 | I16: 1.4 Big Data 9 a data breach is $3.86 million.6 Companies such as Target, Anthem, JPMorgan Chase, Yahoo!, Facebook, Marriott, Equifax, and Home Depot have faced major data breaches cost- ing millions of dollars. The comp...
A17: 1 | B17: hybrid_semantic | C17: 1 | D17: Yes | E17: Business_Analytics_Textbook_Cengage_pg_1_300.pdf | F17: page 32 | G17: 0.033060111 | H17: 3.2682905 | I17: from aircraft to cars to bridges allow us to collect and store vast amounts of data in real time. In the midst of all of this data collection, the term big data has been created. There is no universally accepted definiti...
A18: 1 | B18: hybrid_semantic | C18: 2 | D18: Yes | E18: Business_Analytics_Textbook_Cengage_pg_1_300.pdf | F18: page 33 | G18: 0.032522473 | H18: 3.1498978 | I18: 1.4 Big Data 7 Chapter Title Descriptive Predictive Prescriptive 1 Introduction ● ● ● 2 Descriptive Statistics ● 3 Data Visualization ● 4 Probability: An Introduction to Modeling Uncertainty ● 5 Descriptive Data Mining ●...
A19: 1 | B19: hybrid_semantic | C19: 3 | D19: Yes | E19: Business_Analytics_Textbook_Cengage_pg_1_300.pdf | F19: page 34 | G19: 0.031746034 | H19: 2.440428 | I19: or ser- vices on social media platforms such as Twitter. Audio data are collected from service calls (on a service call, you will often hear “this call may be monitored for quality control”). Video data collected by in-s...
A20: 1 | B20: hybrid_semantic | C20: 4 | D20: No | E20: Business_Analytics_Textbook_Cengage_pg_1_300.pdf | F20: page 28 | G20: 0.014084507 | H20: 2.1510038 | I20: AI is the use of data and computers to make decisions that would have in the past required human intelligence. Often, the computer software mimics the way we understand the human brain functions. Watson became a househol...
A21: 1 | B21: hybrid_semantic | C21: 5 | D21: No | E21: Business_Analytics_Textbook_Cengage_pg_1_300.pdf | F21: page 32 | G21: 0.023809524 | H21: 2.1271214 | I21: with optimi- zation techniques to find good decisions in highly complex and highly uncertain settings. Finally, the techniques of decision analysis can be used to develop an optimal strategy when a decision maker is face...
A22: 2 | B22: keyword | C22: 1 | D22: Yes | E22: Business_Analytics_Textbook_Cengage_pg_1_300.pdf | F22: page 35 | G22: 44.25981 | I22: 1.4 Big Data 9 a data breach is $3.86 million.6 Companies such as Target, Anthem, JPMorgan Chase, Yahoo!, Facebook, Marriott, Equifax, and Home Depot have faced major data breaches cost- ing millions of dollars. The comp...
A23: 2 | B23: keyword | C23: 2 | D23: No | E23: Business_Analytics_Textbook_Cengage_pg_1_300.pdf | F23: page 35 | G23: 15.778287 | I23: on several years of shopping data obtained through its customer loyalty card program. By collecting and analyzing consumer behavior at the individual household level, and better matching its coupon offers to shopper inte...
A24: 2 | B24: keyword | C24: 3 | D24: No | E24: Business_Analytics_Textbook_Cengage_pg_1_300.pdf | F24: page 165 | G24: 14.861037 | I24: case Problem 1: Pelican stores 139 C AS e Pr O blem 1: Peli CA n STO re S Pelican Stores, a division of National Clothing, is a chain of women’s apparel stores operat- ing throughout the country. The chain recently ran a...
A25: 2 | B25: keyword | C25: 4 | D25: No | E25: Business_Analytics_Textbook_Cengage_pg_1_300.pdf | F25: page 255 | G25: 14.0979 | I25: respon- dents need to be analyzed so that Triad can better understand its customers’ specific concerns and respond in an appropriate manner. Table 5.6 contains a small training sample of these com- ments we will use to i...
A26: 2 | B26: keyword | C26: 5 | D26: No | E26: Business_Analytics_Textbook_Cengage_pg_1_300.pdf | F26: page 276 | G26: 13.851866 | I26: involves an Ital- ian item. f. What insight can the grocery store obtain about its purchasers of the Italian fare? 22. Text Mining of Tweets. Companies can learn a lot about customer experiences by monitoring the social...
A27: 2 | B27: vector | C27: 1 | D27: No | E27: Business_Analytics_Textbook_Cengage_pg_1_300.pdf | F27: page 35 | G27: 0.6584376 | I27: on several years of shopping data obtained through its customer loyalty card program. By collecting and analyzing consumer behavior at the individual household level, and better matching its coupon offers to shopper inte...
A28: 2 | B28: vector | C28: 2 | D28: Yes | E28: Business_Analytics_Textbook_Cengage_pg_1_300.pdf | F28: page 35 | G28: 0.6331526 | I28: 1.4 Big Data 9 a data breach is $3.86 million.6 Companies such as Target, Anthem, JPMorgan Chase, Yahoo!, Facebook, Marriott, Equifax, and Home Depot have faced major data breaches cost- ing millions of dollars. The comp...
A29: 2 | B29: vector | C29: 3 | D29: No | E29: Business_Analytics_Textbook_Cengage_pg_1_300.pdf | F29: page 165 | G29: 0.63240105 | I29: case Problem 1: Pelican stores 139 C AS e Pr O blem 1: Peli CA n STO re S Pelican Stores, a division of National Clothing, is a chain of women’s apparel stores operat- ing throughout the country. The chain recently ran a...
A30: 2 | B30: vector | C30: 4 | D30: No | E30: Business_Analytics_Textbook_Cengage_pg_1_300.pdf | F30: page 165 | G30: 0.6231402 | I30: the sales made to people pre- senting the promotional coupons as sales it would not otherwise make. Of course, Pelican also hopes that the promotional customers will continue to shop at its stores. Most of the variables...
A31: 2 | B31: vector | C31: 5 | D31: No | E31: Business_Analytics_Textbook_Cengage_pg_1_300.pdf | F31: page 275 | G31: 0.6134414 | I31: movies, and the average box office earnings of movies in each cluster. How would you describe the movies in each cluster? 18. k-Means Clustering of Trader Joe’ s Stores. Josephine Mater works for the supply-chain analyti...
A32: 2 | B32: hybrid | C32: 1 | D32: Yes | E32: Business_Analytics_Textbook_Cengage_pg_1_300.pdf | F32: page 35 | G32: 0.033060111 | I32: 1.4 Big Data 9 a data breach is $3.86 million.6 Companies such as Target, Anthem, JPMorgan Chase, Yahoo!, Facebook, Marriott, Equifax, and Home Depot have faced major data breaches cost- ing millions of dollars. The comp...
A33: 2 | B33: hybrid | C33: 2 | D33: No | E33: Business_Analytics_Textbook_Cengage_pg_1_300.pdf | F33: page 35 | G33: 0.033060111 | I33: on several years of shopping data obtained through its customer loyalty card program. By collecting and analyzing consumer behavior at the individual household level, and better matching its coupon offers to shopper inte...
... A36: 2 | B36: hybrid | C36: 5 | D36: No | E36: Business_Analytics_Textbook_Cengage_pg_1_300.pdf | F36: page 165 | G36: 0.029386532 | I36: the sales made to people pre- senting the promotional coupons as sales it would not otherwise make. Of course, Pelican also hopes that the promotional customers will continue to shop at its stores. Most of the variables...
A37: 2 | B37: hybrid_semantic | C37: 1 | D37: Yes | E37: Business_Analytics_Textbook_Cengage_pg_1_300.pdf | F37: page 35 | G37: 0.033060111 | H37: 3.0655344 | I37: 1.4 Big Data 9 a data breach is $3.86 million.6 Companies such as Target, Anthem, JPMorgan Chase, Yahoo!, Facebook, Marriott, Equifax, and Home Depot have faced major data breaches cost- ing millions of dollars. The comp...
A38: 2 | B38: hybrid_semantic | C38: 2 | D38: No | E38: Business_Analytics_Textbook_Cengage_pg_1_300.pdf | F38: page 35 | G38: 0.033060111 | H38: 1.9719969 | I38: on several years of shopping data obtained through its customer loyalty card program. By collecting and analyzing consumer behavior at the individual household level, and better matching its coupon offers to shopper inte...
A39: 2 | B39: hybrid_semantic | C39: 3 | D39: No | E39: Business_Analytics_Textbook_Cengage_pg_1_300.pdf | F39: page 165 | G39: 0.029386532 | H39: 1.5788907 | I39: the sales made to people pre- senting the promotional coupons as sales it would not otherwise make. Of course, Pelican also hopes that the promotional customers will continue to shop at its stores. Most of the variables...
A40: 2 | B40: hybrid_semantic | C40: 4 | D40: No | E40: Business_Analytics_Textbook_Cengage_pg_1_300.pdf | F40: page 285 | G40: 0.026878867 | H40: 1.4594345 | I40: if the inter- viewer selected a group of five customers who entered the restaurant together and asked all of them to participate in the sample. Such a group of customers would be likely to exhibit similar characteristics...
A41: 2 | B41: hybrid_semantic | C41: 5 | D41: No | E41: Business_Analytics_Textbook_Cengage_pg_1_300.pdf | F41: page 31 | G41: 0.012195121 | H41: 1.3016958 | I41: analytics. Linear regression, time series analysis, some data-mining techniques, and simulation, often referred to as risk analysis, all fall under the banner of predictive analytics. We dis- cuss all of these techniques...
A42: 3 | B42: keyword | C42: 1 | D42: No | E42: Business_Analytics_Textbook_Cengage_pg_1_300.pdf | F42: page 185 | G42: 15.712019 | I42: to occur if any one of these outcomes occurs. A variety of additional events can be defined for the CP&L project: Ll esst han M more than Thee vent that thep roject is completedi n1 0m onths 8, 9 Thee vent that thep roje...
A43: 3 | B43: keyword | C43: 2 | D43: No | E43: Business_Analytics_Textbook_Cengage_pg_1_300.pdf | F43: page 226 | G43: 12.902727 | I43: 200 chapter 4 Probability: An Introduction to Modeling Uncertainty P R o B l E m S 1. Airline Performance Measures. On-time arrivals, lost baggage, and customer com- plaints are three measures that are typically used to...
A44: 3 | B44: keyword | C44: 3 | D44: No | E44: Business Analytics Overview.pptx | F44: slide 7 | G44: 12.571788 | I44: Investments in Analytics Challenges to Calculate ROI Identify the investments’ actual costs and benefits Sharing infrastructure, such as software, hardware, and data preparation What portion of the costs are directly par...
...

Sheet Answers
A1: Q# | B1: Method | C1: Question | D1: Answer | E1: Answer quality (from Per Question)
A2: 1 | B2: keyword | C2: According to the textbook, what are the four Vs that IBM uses to describe big data? | D2: According to the textbook, IBM describes big data through the **four Vs**: - **Volume** — large amounts of data, from terabytes to exabytes [3] - **Velocity** — data in motion, such as streaming data requiring rapid response [3] - **Variety** — data in many forms, including structured, unstructured, text, and multimedia [3] - **Veracity** — uncertainty in the data due to inconsistency, incompleteness, ambiguity, latency, deception, or model approximations [3] These four Vs are identified as IBM’s description of the big data phenomenon [2]. | E2: =IF('Per Question'!N2="","",'Per Question'!N2)
A3: 1 | B3: vector | C3: According to the textbook, what are the four Vs that IBM uses to describe big data? | D3: According to the textbook, IBM describes big data through the **four Vs**: - **Volume** - **Velocity** - **Variety** - **Veracity** [1][2] | E3: =IF('Per Question'!N3="","",'Per Question'!N3)
A4: 1 | B4: hybrid | C4: According to the textbook, what are the four Vs that IBM uses to describe big data? | D4: According to the textbook, IBM describes big data through the **four Vs**: - **Volume** - **Velocity** - **Variety** - **Veracity** [1][2] | E4: =IF('Per Question'!N4="","",'Per Question'!N4)
A5: 1 | B5: hybrid_semantic | C5: According to the textbook, what are the four Vs that IBM uses to describe big data? | D5: According to the textbook, IBM describes big data using the **four Vs**: - **Volume** - **Velocity** - **Variety** - **Veracity** [1][2] | E5: =IF('Per Question'!N5="","",'Per Question'!N5)
A6: 2 | B6: keyword | C6: How many pieces of direct mail does Kroger send to its customers each quarter, and how are the coupons chosen? | D6: Kroger sends **over 11 million pieces of direct mail** to its customers each quarter [1]. The coupons are chosen by **tailoring 12 coupons in each quarterly mailer to each household**, based on **several years of shopping data collected through Kroger’s customer loyalty card program** [1]. | E6: =IF('Per Question'!N6="","",'Per Question'!N6)
A7: 2 | B7: vector | C7: How many pieces of direct mail does Kroger send to its customers each quarter, and how are the coupons chosen? | D7: Kroger sends **over 11 million pieces of direct mail** to its customers each quarter [2]. The coupons are **tailored to each household** based on **several years of shopping data** collected through Kroger’s **customer loyalty card program** [2]. This allows Kroger to better match coupon offers to individual shopper interests [1]. | E7: =IF('Per Question'!N7="","",'Per Question'!N7)
A8: 2 | B8: hybrid | C8: How many pieces of direct mail does Kroger send to its customers each quarter, and how are the coupons chosen? | D8: Kroger sends **over 11 million pieces of direct mail** to its customers each quarter [1]. The coupons are chosen by **tailoring 12 coupons in each mailer to each household**, based on **several years of shopping data collected through Kroger’s customer loyalty card program** [1]. Kroger uses this data to analyze consumer behavior at the individual household level and better match coupon offers to shopper interests [2]. | E8: =IF('Per Question'!N8="","",'Per Question'!N8)
A9: 2 | B9: hybrid_semantic | C9: How many pieces of direct mail does Kroger send to its customers each quarter, and how are the coupons chosen? | D9: Kroger sends **over 11 million pieces of direct mail** to its customers each quarter [1]. The coupons are chosen by **tailoring 12 coupons in each mailer to each household**, based on **several years of shopping data collected through Kroger’s customer loyalty card program** [1]. Kroger uses this data to analyze consumer behavior at the individual household level and better match coupon offers to shopper interests [2]. | E9: =IF('Per Question'!N9="","",'Per Question'!N9)
A10: 3 | B10: keyword | C10: What share of data science initiatives end up not succeeding, and what typically goes wrong? | D10: The provided sources do **not** state what share of data science initiatives end up not succeeding, nor do they explain what typically goes wrong. What the sources do cover: - Random experiments, outcomes, and probability examples [1]. - An airline performance data problem involving on-time arrivals, mishandled baggage, and customer complaints [2]. - Challenges in calculating ROI for analytics investments, such as identifying actual costs/benefits and separating shared infrastructure costs from project-specific costs [3]. - Key analytics trends, including automation/AutoML, regulation and governance, bias/ethics, and model management across the ML life cycle [4]. - A general description of business analytics as prediction/prescription, analytical modeling, and decision support, with examples in healthcare and decision analytics [5]. | E10: =IF('Per Question'!N10="","",'Per Question'!N10)
A11: 3 | B11: vector | C11: What share of data science initiatives end up not succeeding, and what typically goes wrong? | D11: - **Share not succeeding:** The sources state that the failure rate for analytics projects is **over 80%** [1]. - **What typically goes wrong:** Common analytics project pitfalls include: - **Data issues** [1] - **Solving the wrong problem** [1] - **Making the model too complex** [1] - **Treating deployment as the last step instead of planning proactively** [1] - **Forgetting ethics** [1] - **Overlooking culture** [1] | E11: =IF('Per Question'!N11="","",'Per Question'!N11)
A12: 3 | B12: hybrid | C12: What share of data science initiatives end up not succeeding, and what typically goes wrong? | D12: The sources report that the failure rate for analytics projects is **over 80%** [4]. Common reasons they go wrong include: - **Data issues** [4] - **Solving the wrong problem** [4] - **Making the model too complex** [4] - **Treating deployment as the last step instead of planning proactively** [4] - **Forgetting ethics** [4] - **Overlooking culture** [4] | E12: =IF('Per Question'!N12="","",'Per Question'!N12)
A13: 3 | B13: hybrid_semantic | C13: What share of data science initiatives end up not succeeding, and what typically goes wrong? | D13: The sources say that **over 80% of analytics projects fail** [3]. They do not use the exact phrase “data science initiatives,” but they list common failure causes as: - **Data issues** [3] - **Solving the wrong problem** [3] - **Models that are too complex**, rather than simple and explainable [3] - **Treating deployment as the last step** instead of planning proactively [3] - **Forgetting ethics** [3] - **Overlooking culture** [3] | E13: =IF('Per Question'!N13="","",'Per Question'!N13)
... A33: 8 | B33: hybrid_semantic | C33: What was Amazon's total revenue in 2023? | D33: The provided sources do not contain Amazon’s total revenue in 2023. What the sources do cover: - Amazon appears in a list of top global companies by market value, but no revenue figures are given [1]. - Amazon.com is mentioned as an organization that has embraced analytics [3]. - The other sources include sample revenue/cost tables for “Gossamer Industries,” not Amazon [2][4][5]. | E33: =IF('Per Question'!N33="","",'Per Question'!N33)
